<robot xmlns:xacro="http://www.ros.org/wiki/xacro" name="simple_rover">

    <!-- Base Link -->
    <link name="base_link">
        <visual>
            <geometry>
                <box size="1 0.5 0.2"/>
            </geometry>
            <material name="blue"/>
        </visual>
        <collision>
            <geometry>
                <box size="1 0.5 0.2"/>
            </geometry>
        </collision>
        <inertial>
            <mass value="10"/>
            <origin xyz="0 0 0"/>
            <inertia ixx="0.1" ixy="0" ixz="0" iyy="0.1" iyz="0" izz="0.1"/>
        </inertial>
    </link>

    <!-- Wheel Macro Definition -->
    <xacro:macro name="wheel" params="name parent x y z">
        <joint name="${name}_joint" type="continuous">
            <parent link="${parent}"/>
            <child link="${name}"/>
            <origin xyz="${x} ${y} ${z}" rpy="0 0 0"/>
        </joint>

        <link name="${name}">
            <visual>
                <geometry>
                    <cylinder radius="0.1" length="0.05"/>
                </geometry>
                <material name="black"/>
            </visual>
            <collision>
                <geometry>
                    <cylinder radius="0.1" length="0.05"/>
                </geometry>
            </collision>
            <inertial>
                <mass value="1"/>
                <origin xyz="0 0 0"/>
                <inertia ixx="0.01" ixy="0" ixz="0" iyy="0.01" iyz="0" izz="0.01"/>
            </inertial>
        </link>
    </xacro:macro>

    <!-- Wheels -->
    <xacro:wheel name="front_left_wheel" parent="base_link" x="0.4" y="0.25" z="0"/>
    <xacro:wheel name="front_right_wheel" parent="base_link" x="0.4" y="-0.25" z="0"/>
    <xacro:wheel name="rear_left_wheel" parent="base_link" x="-0.4" y="0.25" z="0"/>
    <xacro:wheel name="rear_right_wheel" parent="base_link" x="-0.4" y="-0.25" z="0"/>

    <!-- Camera -->
    <link name="camera_link">
        <visual>
            <geometry>
                <box size="0.1 0.1 0.1"/>
            </geometry>
            <material name="green"/>
        </visual>
        <collision>
            <geometry>
                <box size="0.1 0.1 0.1"/>
            </geometry>
        </collision>
        <inertial>
            <mass value="0.1"/>
            <origin xyz="0 0 0"/>
            <inertia ixx="0.001" ixy="0" ixz="0" iyy="0.001" iyz="0" izz="0.001"/>
        </inertial>
    </link>

    <joint name="camera_joint" type="fixed">
        <parent link="base_link"/>
        <child link="camera_link"/>
        <origin xyz="0.5 0 0.2" rpy="0 0 0"/>
    </joint>

    <!-- Gazebo Camera Sensor -->
    <gazebo reference="camera_link">
        <sensor type="camera" name="camera_sensor">
            <update_rate>30</update_rate>
            <camera>
                <horizontal_fov>1.047</horizontal_fov>
                <image>
                    <width>640</width>
                    <height>480</height>
                    <format>R8G8B8</format>
                </image>
                <clip>
                    <near>0.1</near>
                    <far>100</far>
                </clip>
            </camera>
            <plugin name="camera_controller" filename="libgazebo_ros_camera.so">
                <robotNamespace>/</robotNamespace>
                <cameraName>camera</cameraName>
                <imageTopicName>image_raw</imageTopicName>
                <cameraInfoTopicName>camera_info</cameraInfoTopicName>
                <frameName>camera_link</frameName>
            </plugin>
        </sensor>
    </gazebo>

    <!-- Differential Drive Controller -->
    <gazebo>
        <plugin name="diff_drive_controller" filename="libgazebo_ros_diff_drive.so">
            <robotNamespace>/</robotNamespace>
            <commandTopic>cmd_vel</commandTopic>
            <odometryTopic>odom</odometryTopic>
            <odometryFrame>odom</odometryFrame>
            <robotBaseFrame>base_link</robotBaseFrame>
            <leftWheelJoint>front_left_wheel_joint rear_left_wheel_joint</leftWheelJoint>
            <rightWheelJoint>front_right_wheel_joint rear_right_wheel_joint</rightWheelJoint>
            <wheelSeparation>0.5</wheelSeparation>
            <wheelDiameter>0.2</wheelDiameter>
            <publishWheelTF>true</publishWheelTF>
            <publishWheelJointState>true</publishWheelJointState>
        </plugin>
    </gazebo>

</robot>
