<?xml version="1.0"?>
<xacro:macro xmlns:xacro="http://www.ros.org/wiki/xacro" name="wheel" params="name parent x y z">
    <!-- Joint definition -->
    <joint name="${name}_joint" type="continuous">
        <parent link="${parent}"/>
        <child link="${name}"/>
        <origin xyz="${x} ${y} ${z}" rpy="0 0 0"/>
    </joint>

    <!-- Link definition -->
    <link name="${name}">
        <visual>
            <geometry>
                <cylinder radius="0.1" length="0.05"/>
            </geometry>
            <material name="black"/>
        </visual>
        <collision>
            <geometry>
                <cylinder radius="0.1" length="0.05"/>
            </geometry>
        </collision>
        <inertial>
            <mass value="1"/>
            <origin xyz="0 0 0"/>
            <inertia ixx="0.01" ixy="0" ixz="0" iyy="0.01" iyz="0" izz="0.01"/>
        </inertial>
    </link>
</xacro:macro>
